[Sat Mar 20 19:54:42.669536 2021] [wsgi:error] [pid 212786:tid 140398061483776] [remote 103.119.102.3:36844] mod_wsgi (pid=212786): Exception occurred processing WSGI script '/home/salesvizion/salesvizion/salesvizion/wsgi.py'.
[Sat Mar 20 19:54:42.690444 2021] [wsgi:error] [pid 212786:tid 140398061483776] [remote 103.119.102.3:36844] Traceback (most recent call last):
[Sat Mar 20 19:54:42.690799 2021] [wsgi:error] [pid 212786:tid 140398061483776] [remote 103.119.102.3:36844]   File "/home/salesvizion/salesvizion/env/lib/python3.8/site-packages/django/db/backends/base/base.py", line 217, in ensure_connection
[Sat Mar 20 19:54:42.690869 2021] [wsgi:error] [pid 212786:tid 140398061483776] [remote 103.119.102.3:36844]     self.connect()
[Sat Mar 20 19:54:42.690953 2021] [wsgi:error] [pid 212786:tid 140398061483776] [remote 103.119.102.3:36844]   File "/home/salesvizion/salesvizion/env/lib/python3.8/site-packages/django/db/backends/base/base.py", line 195, in connect
[Sat Mar 20 19:54:42.691002 2021] [wsgi:error] [pid 212786:tid 140398061483776] [remote 103.119.102.3:36844]     self.connection = self.get_new_connection(conn_params)
[Sat Mar 20 19:54:42.691048 2021] [wsgi:error] [pid 212786:tid 140398061483776] [remote 103.119.102.3:36844]   File "/home/salesvizion/salesvizion/env/lib/python3.8/site-packages/django/db/backends/mysql/base.py", line 227, in get_new_connection
[Sat Mar 20 19:54:42.691089 2021] [wsgi:error] [pid 212786:tid 140398061483776] [remote 103.119.102.3:36844]     return Database.connect(**conn_params)
[Sat Mar 20 19:54:42.691132 2021] [wsgi:error] [pid 212786:tid 140398061483776] [remote 103.119.102.3:36844]   File "/home/salesvizion/salesvizion/env/lib/python3.8/site-packages/MySQLdb/__init__.py", line 130, in Connect
[Sat Mar 20 19:54:42.691172 2021] [wsgi:error] [pid 212786:tid 140398061483776] [remote 103.119.102.3:36844]     return Connection(*args, **kwargs)
[Sat Mar 20 19:54:42.691214 2021] [wsgi:error] [pid 212786:tid 140398061483776] [remote 103.119.102.3:36844]   File "/home/salesvizion/salesvizion/env/lib/python3.8/site-packages/MySQLdb/connections.py", line 185, in __init__
[Sat Mar 20 19:54:42.691255 2021] [wsgi:error] [pid 212786:tid 140398061483776] [remote 103.119.102.3:36844]     super().__init__(*args, **kwargs2)
[Sat Mar 20 19:54:42.691342 2021] [wsgi:error] [pid 212786:tid 140398061483776] [remote 103.119.102.3:36844] MySQLdb._exceptions.OperationalError: (2003, "Can't connect to MySQL server on '127.0.0.1' (111)")
[Sat Mar 20 19:54:42.691417 2021] [wsgi:error] [pid 212786:tid 140398061483776] [remote 103.119.102.3:36844] 
[Sat Mar 20 19:54:42.691460 2021] [wsgi:error] [pid 212786:tid 140398061483776] [remote 103.119.102.3:36844] The above exception was the direct cause of the following exception:
[Sat Mar 20 19:54:42.691490 2021] [wsgi:error] [pid 212786:tid 140398061483776] [remote 103.119.102.3:36844] 
[Sat Mar 20 19:54:42.691532 2021] [wsgi:error] [pid 212786:tid 140398061483776] [remote 103.119.102.3:36844] Traceback (most recent call last):
[Sat Mar 20 19:54:42.691746 2021] [wsgi:error] [pid 212786:tid 140398061483776] [remote 103.119.102.3:36844]   File "/home/salesvizion/salesvizion/env/lib/python3.8/site-packages/django/core/handlers/exception.py", line 34, in inner
[Sat Mar 20 19:54:42.691808 2021] [wsgi:error] [pid 212786:tid 140398061483776] [remote 103.119.102.3:36844]     response = get_response(request)
[Sat Mar 20 19:54:42.691854 2021] [wsgi:error] [pid 212786:tid 140398061483776] [remote 103.119.102.3:36844]   File "/home/salesvizion/salesvizion/env/lib/python3.8/site-packages/django/core/handlers/base.py", line 115, in _get_response
[Sat Mar 20 19:54:42.691895 2021] [wsgi:error] [pid 212786:tid 140398061483776] [remote 103.119.102.3:36844]     response = self.process_exception_by_middleware(e, request)
[Sat Mar 20 19:54:42.691938 2021] [wsgi:error] [pid 212786:tid 140398061483776] [remote 103.119.102.3:36844]   File "/home/salesvizion/salesvizion/env/lib/python3.8/site-packages/django/core/handlers/base.py", line 113, in _get_response
[Sat Mar 20 19:54:42.691977 2021] [wsgi:error] [pid 212786:tid 140398061483776] [remote 103.119.102.3:36844]     response = wrapped_callback(request, *callback_args, **callback_kwargs)
[Sat Mar 20 19:54:42.692077 2021] [wsgi:error] [pid 212786:tid 140398061483776] [remote 103.119.102.3:36844]   File "/home/salesvizion/salesvizion/salesvizionusers/views.py", line 25, in login
[Sat Mar 20 19:54:42.692129 2021] [wsgi:error] [pid 212786:tid 140398061483776] [remote 103.119.102.3:36844]     if form.is_valid():
[Sat Mar 20 19:54:42.692172 2021] [wsgi:error] [pid 212786:tid 140398061483776] [remote 103.119.102.3:36844]   File "/home/salesvizion/salesvizion/env/lib/python3.8/site-packages/django/forms/forms.py", line 185, in is_valid
[Sat Mar 20 19:54:42.692211 2021] [wsgi:error] [pid 212786:tid 140398061483776] [remote 103.119.102.3:36844]     return self.is_bound and not self.errors
[Sat Mar 20 19:54:42.692254 2021] [wsgi:error] [pid 212786:tid 140398061483776] [remote 103.119.102.3:36844]   File "/home/salesvizion/salesvizion/env/lib/python3.8/site-packages/django/forms/forms.py", line 180, in errors
[Sat Mar 20 19:54:42.692294 2021] [wsgi:error] [pid 212786:tid 140398061483776] [remote 103.119.102.3:36844]     self.full_clean()
[Sat Mar 20 19:54:42.692336 2021] [wsgi:error] [pid 212786:tid 140398061483776] [remote 103.119.102.3:36844]   File "/home/salesvizion/salesvizion/env/lib/python3.8/site-packages/django/forms/forms.py", line 381, in full_clean
[Sat Mar 20 19:54:42.692375 2021] [wsgi:error] [pid 212786:tid 140398061483776] [remote 103.119.102.3:36844]     self._clean_fields()
[Sat Mar 20 19:54:42.692417 2021] [wsgi:error] [pid 212786:tid 140398061483776] [remote 103.119.102.3:36844]   File "/home/salesvizion/salesvizion/env/lib/python3.8/site-packages/django/forms/forms.py", line 402, in _clean_fields
[Sat Mar 20 19:54:42.692456 2021] [wsgi:error] [pid 212786:tid 140398061483776] [remote 103.119.102.3:36844]     value = getattr(self, 'clean_%s' % name)()
[Sat Mar 20 19:54:42.692499 2021] [wsgi:error] [pid 212786:tid 140398061483776] [remote 103.119.102.3:36844]   File "/home/salesvizion/salesvizion/salesvizionusers/forms.py", line 28, in clean_username
[Sat Mar 20 19:54:42.692573 2021] [wsgi:error] [pid 212786:tid 140398061483776] [remote 103.119.102.3:36844]     if not User.objects.filter(username = data).exists():
[Sat Mar 20 19:54:42.692653 2021] [wsgi:error] [pid 212786:tid 140398061483776] [remote 103.119.102.3:36844]   File "/home/salesvizion/salesvizion/env/lib/python3.8/site-packages/django/db/models/query.py", line 766, in exists
[Sat Mar 20 19:54:42.692705 2021] [wsgi:error] [pid 212786:tid 140398061483776] [remote 103.119.102.3:36844]     return self.query.has_results(using=self.db)
[Sat Mar 20 19:54:42.692749 2021] [wsgi:error] [pid 212786:tid 140398061483776] [remote 103.119.102.3:36844]   File "/home/salesvizion/salesvizion/env/lib/python3.8/site-packages/django/db/models/sql/query.py", line 522, in has_results
[Sat Mar 20 19:54:42.692789 2021] [wsgi:error] [pid 212786:tid 140398061483776] [remote 103.119.102.3:36844]     return compiler.has_results()
[Sat Mar 20 19:54:42.692831 2021] [wsgi:error] [pid 212786:tid 140398061483776] [remote 103.119.102.3:36844]   File "/home/salesvizion/salesvizion/env/lib/python3.8/site-packages/django/db/models/sql/compiler.py", line 1067, in has_results
[Sat Mar 20 19:54:42.692870 2021] [wsgi:error] [pid 212786:tid 140398061483776] [remote 103.119.102.3:36844]     return bool(self.execute_sql(SINGLE))
[Sat Mar 20 19:54:42.692912 2021] [wsgi:error] [pid 212786:tid 140398061483776] [remote 103.119.102.3:36844]   File "/home/salesvizion/salesvizion/env/lib/python3.8/site-packages/django/db/models/sql/compiler.py", line 1095, in execute_sql
[Sat Mar 20 19:54:42.692951 2021] [wsgi:error] [pid 212786:tid 140398061483776] [remote 103.119.102.3:36844]     cursor = self.connection.cursor()
[Sat Mar 20 19:54:42.692993 2021] [wsgi:error] [pid 212786:tid 140398061483776] [remote 103.119.102.3:36844]   File "/home/salesvizion/salesvizion/env/lib/python3.8/site-packages/django/db/backends/base/base.py", line 256, in cursor
[Sat Mar 20 19:54:42.693075 2021] [wsgi:error] [pid 212786:tid 140398061483776] [remote 103.119.102.3:36844]     return self._cursor()
[Sat Mar 20 19:54:42.693131 2021] [wsgi:error] [pid 212786:tid 140398061483776] [remote 103.119.102.3:36844]   File "/home/salesvizion/salesvizion/env/lib/python3.8/site-packages/django/db/backends/base/base.py", line 233, in _cursor
[Sat Mar 20 19:54:42.693173 2021] [wsgi:error] [pid 212786:tid 140398061483776] [remote 103.119.102.3:36844]     self.ensure_connection()
[Sat Mar 20 19:54:42.693244 2021] [wsgi:error] [pid 212786:tid 140398061483776] [remote 103.119.102.3:36844]   File "/home/salesvizion/salesvizion/env/lib/python3.8/site-packages/django/db/backends/base/base.py", line 217, in ensure_connection
[Sat Mar 20 19:54:42.693289 2021] [wsgi:error] [pid 212786:tid 140398061483776] [remote 103.119.102.3:36844]     self.connect()
[Sat Mar 20 19:54:42.693332 2021] [wsgi:error] [pid 212786:tid 140398061483776] [remote 103.119.102.3:36844]   File "/home/salesvizion/salesvizion/env/lib/python3.8/site-packages/django/db/utils.py", line 89, in __exit__
[Sat Mar 20 19:54:42.693372 2021] [wsgi:error] [pid 212786:tid 140398061483776] [remote 103.119.102.3:36844]     raise dj_exc_value.with_traceback(traceback) from exc_value
[Sat Mar 20 19:54:42.693416 2021] [wsgi:error] [pid 212786:tid 140398061483776] [remote 103.119.102.3:36844]   File "/home/salesvizion/salesvizion/env/lib/python3.8/site-packages/django/db/backends/base/base.py", line 217, in ensure_connection
[Sat Mar 20 19:54:42.693455 2021] [wsgi:error] [pid 212786:tid 140398061483776] [remote 103.119.102.3:36844]     self.connect()
[Sat Mar 20 19:54:42.693497 2021] [wsgi:error] [pid 212786:tid 140398061483776] [remote 103.119.102.3:36844]   File "/home/salesvizion/salesvizion/env/lib/python3.8/site-packages/django/db/backends/base/base.py", line 195, in connect
[Sat Mar 20 19:54:42.693541 2021] [wsgi:error] [pid 212786:tid 140398061483776] [remote 103.119.102.3:36844]     self.connection = self.get_new_connection(conn_params)
[Sat Mar 20 19:54:42.693583 2021] [wsgi:error] [pid 212786:tid 140398061483776] [remote 103.119.102.3:36844]   File "/home/salesvizion/salesvizion/env/lib/python3.8/site-packages/django/db/backends/mysql/base.py", line 227, in get_new_connection
[Sat Mar 20 19:54:42.693637 2021] [wsgi:error] [pid 212786:tid 140398061483776] [remote 103.119.102.3:36844]     return Database.connect(**conn_params)
[Sat Mar 20 19:54:42.693714 2021] [wsgi:error] [pid 212786:tid 140398061483776] [remote 103.119.102.3:36844]   File "/home/salesvizion/salesvizion/env/lib/python3.8/site-packages/MySQLdb/__init__.py", line 130, in Connect
[Sat Mar 20 19:54:42.693758 2021] [wsgi:error] [pid 212786:tid 140398061483776] [remote 103.119.102.3:36844]     return Connection(*args, **kwargs)
[Sat Mar 20 19:54:42.693801 2021] [wsgi:error] [pid 212786:tid 140398061483776] [remote 103.119.102.3:36844]   File "/home/salesvizion/salesvizion/env/lib/python3.8/site-packages/MySQLdb/connections.py", line 185, in __init__
[Sat Mar 20 19:54:42.693841 2021] [wsgi:error] [pid 212786:tid 140398061483776] [remote 103.119.102.3:36844]     super().__init__(*args, **kwargs2)
[Sat Mar 20 19:54:42.693901 2021] [wsgi:error] [pid 212786:tid 140398061483776] [remote 103.119.102.3:36844] django.db.utils.OperationalError: (2003, "Can't connect to MySQL server on '127.0.0.1' (111)")
[Sat Mar 20 19:54:42.693964 2021] [wsgi:error] [pid 212786:tid 140398061483776] [remote 103.119.102.3:36844] 
[Sat Mar 20 19:54:42.694005 2021] [wsgi:error] [pid 212786:tid 140398061483776] [remote 103.119.102.3:36844] During handling of the above exception, another exception occurred:
[Sat Mar 20 19:54:42.694034 2021] [wsgi:error] [pid 212786:tid 140398061483776] [remote 103.119.102.3:36844] 
[Sat Mar 20 19:54:42.694082 2021] [wsgi:error] [pid 212786:tid 140398061483776] [remote 103.119.102.3:36844] Traceback (most recent call last):
[Sat Mar 20 19:54:42.694199 2021] [wsgi:error] [pid 212786:tid 140398061483776] [remote 103.119.102.3:36844]   File "/home/salesvizion/salesvizion/env/lib/python3.8/site-packages/django/core/handlers/exception.py", line 34, in inner
[Sat Mar 20 19:54:42.694295 2021] [wsgi:error] [pid 212786:tid 140398061483776] [remote 103.119.102.3:36844]     response = get_response(request)
[Sat Mar 20 19:54:42.694351 2021] [wsgi:error] [pid 212786:tid 140398061483776] [remote 103.119.102.3:36844]   File "/home/salesvizion/salesvizion/env/lib/python3.8/site-packages/django/utils/deprecation.py", line 94, in __call__
[Sat Mar 20 19:54:42.694393 2021] [wsgi:error] [pid 212786:tid 140398061483776] [remote 103.119.102.3:36844]     response = response or self.get_response(request)
[Sat Mar 20 19:54:42.694436 2021] [wsgi:error] [pid 212786:tid 140398061483776] [remote 103.119.102.3:36844]   File "/home/salesvizion/salesvizion/env/lib/python3.8/site-packages/django/core/handlers/exception.py", line 36, in inner
[Sat Mar 20 19:54:42.694477 2021] [wsgi:error] [pid 212786:tid 140398061483776] [remote 103.119.102.3:36844]     response = response_for_exception(request, exc)
[Sat Mar 20 19:54:42.694534 2021] [wsgi:error] [pid 212786:tid 140398061483776] [remote 103.119.102.3:36844]   File "/home/salesvizion/salesvizion/env/lib/python3.8/site-packages/django/core/handlers/exception.py", line 90, in response_for_exception
[Sat Mar 20 19:54:42.694587 2021] [wsgi:error] [pid 212786:tid 140398061483776] [remote 103.119.102.3:36844]     response = handle_uncaught_exception(request, get_resolver(get_urlconf()), sys.exc_info())
[Sat Mar 20 19:54:42.694652 2021] [wsgi:error] [pid 212786:tid 140398061483776] [remote 103.119.102.3:36844]   File "/home/salesvizion/salesvizion/env/lib/python3.8/site-packages/django/core/handlers/exception.py", line 125, in handle_uncaught_exception
[Sat Mar 20 19:54:42.694704 2021] [wsgi:error] [pid 212786:tid 140398061483776] [remote 103.119.102.3:36844]     return debug.technical_500_response(request, *exc_info)
[Sat Mar 20 19:54:42.694748 2021] [wsgi:error] [pid 212786:tid 140398061483776] [remote 103.119.102.3:36844]   File "/home/salesvizion/salesvizion/env/lib/python3.8/site-packages/django/views/debug.py", line 94, in technical_500_response
[Sat Mar 20 19:54:42.694788 2021] [wsgi:error] [pid 212786:tid 140398061483776] [remote 103.119.102.3:36844]     html = reporter.get_traceback_html()
[Sat Mar 20 19:54:42.694837 2021] [wsgi:error] [pid 212786:tid 140398061483776] [remote 103.119.102.3:36844]   File "/home/salesvizion/salesvizion/env/lib/python3.8/site-packages/django/views/debug.py", line 332, in get_traceback_html
[Sat Mar 20 19:54:42.694876 2021] [wsgi:error] [pid 212786:tid 140398061483776] [remote 103.119.102.3:36844]     t = DEBUG_ENGINE.from_string(fh.read())
[Sat Mar 20 19:54:42.694918 2021] [wsgi:error] [pid 212786:tid 140398061483776] [remote 103.119.102.3:36844]   File "/usr/lib/python3.8/encodings/ascii.py", line 26, in decode
[Sat Mar 20 19:54:42.694957 2021] [wsgi:error] [pid 212786:tid 140398061483776] [remote 103.119.102.3:36844]     return codecs.ascii_decode(input, self.errors)[0]
[Sat Mar 20 19:54:42.695013 2021] [wsgi:error] [pid 212786:tid 140398061483776] [remote 103.119.102.3:36844] UnicodeDecodeError: 'ascii' codec can't decode byte 0xe2 in position 9735: ordinal not in range(128)
[Sat Mar 20 19:54:42.695075 2021] [wsgi:error] [pid 212786:tid 140398061483776] [remote 103.119.102.3:36844] 
[Sat Mar 20 19:54:42.695116 2021] [wsgi:error] [pid 212786:tid 140398061483776] [remote 103.119.102.3:36844] During handling of the above exception, another exception occurred:
[Sat Mar 20 19:54:42.695146 2021] [wsgi:error] [pid 212786:tid 140398061483776] [remote 103.119.102.3:36844] 
[Sat Mar 20 19:54:42.695187 2021] [wsgi:error] [pid 212786:tid 140398061483776] [remote 103.119.102.3:36844] Traceback (most recent call last):
[Sat Mar 20 19:54:42.695284 2021] [wsgi:error] [pid 212786:tid 140398061483776] [remote 103.119.102.3:36844]   File "/home/salesvizion/salesvizion/env/lib/python3.8/site-packages/django/core/handlers/exception.py", line 34, in inner
[Sat Mar 20 19:54:42.695331 2021] [wsgi:error] [pid 212786:tid 140398061483776] [remote 103.119.102.3:36844]     response = get_response(request)
[Sat Mar 20 19:54:42.695389 2021] [wsgi:error] [pid 212786:tid 140398061483776] [remote 103.119.102.3:36844]   File "/home/salesvizion/salesvizion/env/lib/python3.8/site-packages/django/utils/deprecation.py", line 94, in __call__
[Sat Mar 20 19:54:42.695448 2021] [wsgi:error] [pid 212786:tid 140398061483776] [remote 103.119.102.3:36844]     response = response or self.get_response(request)
[Sat Mar 20 19:54:42.695502 2021] [wsgi:error] [pid 212786:tid 140398061483776] [remote 103.119.102.3:36844]   File "/home/salesvizion/salesvizion/env/lib/python3.8/site-packages/django/core/handlers/exception.py", line 36, in inner
[Sat Mar 20 19:54:42.695543 2021] [wsgi:error] [pid 212786:tid 140398061483776] [remote 103.119.102.3:36844]     response = response_for_exception(request, exc)
[Sat Mar 20 19:54:42.695599 2021] [wsgi:error] [pid 212786:tid 140398061483776] [remote 103.119.102.3:36844]   File "/home/salesvizion/salesvizion/env/lib/python3.8/site-packages/django/core/handlers/exception.py", line 90, in response_for_exception
[Sat Mar 20 19:54:42.695676 2021] [wsgi:error] [pid 212786:tid 140398061483776] [remote 103.119.102.3:36844]     response = handle_uncaught_exception(request, get_resolver(get_urlconf()), sys.exc_info())
[Sat Mar 20 19:54:42.695732 2021] [wsgi:error] [pid 212786:tid 140398061483776] [remote 103.119.102.3:36844]   File "/home/salesvizion/salesvizion/env/lib/python3.8/site-packages/django/core/handlers/exception.py", line 125, in handle_uncaught_exception
[Sat Mar 20 19:54:42.695775 2021] [wsgi:error] [pid 212786:tid 140398061483776] [remote 103.119.102.3:36844]     return debug.technical_500_response(request, *exc_info)
[Sat Mar 20 19:54:42.695817 2021] [wsgi:error] [pid 212786:tid 140398061483776] [remote 103.119.102.3:36844]   File "/home/salesvizion/salesvizion/env/lib/python3.8/site-packages/django/views/debug.py", line 94, in technical_500_response
[Sat Mar 20 19:54:42.695857 2021] [wsgi:error] [pid 212786:tid 140398061483776] [remote 103.119.102.3:36844]     html = reporter.get_traceback_html()
[Sat Mar 20 19:54:42.695898 2021] [wsgi:error] [pid 212786:tid 140398061483776] [remote 103.119.102.3:36844]   File "/home/salesvizion/salesvizion/env/lib/python3.8/site-packages/django/views/debug.py", line 332, in get_traceback_html
[Sat Mar 20 19:54:42.695938 2021] [wsgi:error] [pid 212786:tid 140398061483776] [remote 103.119.102.3:36844]     t = DEBUG_ENGINE.from_string(fh.read())
[Sat Mar 20 19:54:42.695980 2021] [wsgi:error] [pid 212786:tid 140398061483776] [remote 103.119.102.3:36844]   File "/usr/lib/python3.8/encodings/ascii.py", line 26, in decode
[Sat Mar 20 19:54:42.696019 2021] [wsgi:error] [pid 212786:tid 140398061483776] [remote 103.119.102.3:36844]     return codecs.ascii_decode(input, self.errors)[0]
[Sat Mar 20 19:54:42.696073 2021] [wsgi:error] [pid 212786:tid 140398061483776] [remote 103.119.102.3:36844] UnicodeDecodeError: 'ascii' codec can't decode byte 0xe2 in position 9735: ordinal not in range(128)
[Sat Mar 20 19:54:42.696137 2021] [wsgi:error] [pid 212786:tid 140398061483776] [remote 103.119.102.3:36844] 
[Sat Mar 20 19:54:42.696179 2021] [wsgi:error] [pid 212786:tid 140398061483776] [remote 103.119.102.3:36844] During handling of the above exception, another exception occurred:
[Sat Mar 20 19:54:42.696208 2021] [wsgi:error] [pid 212786:tid 140398061483776] [remote 103.119.102.3:36844] 
[Sat Mar 20 19:54:42.696249 2021] [wsgi:error] [pid 212786:tid 140398061483776] [remote 103.119.102.3:36844] Traceback (most recent call last):
[Sat Mar 20 19:54:42.696344 2021] [wsgi:error] [pid 212786:tid 140398061483776] [remote 103.119.102.3:36844]   File "/home/salesvizion/salesvizion/env/lib/python3.8/site-packages/django/core/handlers/exception.py", line 34, in inner
[Sat Mar 20 19:54:42.696391 2021] [wsgi:error] [pid 212786:tid 140398061483776] [remote 103.119.102.3:36844]     response = get_response(request)
[Sat Mar 20 19:54:42.696434 2021] [wsgi:error] [pid 212786:tid 140398061483776] [remote 103.119.102.3:36844]   File "/home/salesvizion/salesvizion/env/lib/python3.8/site-packages/django/utils/deprecation.py", line 94, in __call__
[Sat Mar 20 19:54:42.696536 2021] [wsgi:error] [pid 212786:tid 140398061483776] [remote 103.119.102.3:36844]     response = response or self.get_response(request)
[Sat Mar 20 19:54:42.696605 2021] [wsgi:error] [pid 212786:tid 140398061483776] [remote 103.119.102.3:36844]   File "/home/salesvizion/salesvizion/env/lib/python3.8/site-packages/django/core/handlers/exception.py", line 36, in inner
[Sat Mar 20 19:54:42.696673 2021] [wsgi:error] [pid 212786:tid 140398061483776] [remote 103.119.102.3:36844]     response = response_for_exception(request, exc)
[Sat Mar 20 19:54:42.696727 2021] [wsgi:error] [pid 212786:tid 140398061483776] [remote 103.119.102.3:36844]   File "/home/salesvizion/salesvizion/env/lib/python3.8/site-packages/django/core/handlers/exception.py", line 90, in response_for_exception
[Sat Mar 20 19:54:42.696769 2021] [wsgi:error] [pid 212786:tid 140398061483776] [remote 103.119.102.3:36844]     response = handle_uncaught_exception(request, get_resolver(get_urlconf()), sys.exc_info())
[Sat Mar 20 19:54:42.696812 2021] [wsgi:error] [pid 212786:tid 140398061483776] [remote 103.119.102.3:36844]   File "/home/salesvizion/salesvizion/env/lib/python3.8/site-packages/django/core/handlers/exception.py", line 125, in handle_uncaught_exception
[Sat Mar 20 19:54:42.696852 2021] [wsgi:error] [pid 212786:tid 140398061483776] [remote 103.119.102.3:36844]     return debug.technical_500_response(request, *exc_info)
[Sat Mar 20 19:54:42.696895 2021] [wsgi:error] [pid 212786:tid 140398061483776] [remote 103.119.102.3:36844]   File "/home/salesvizion/salesvizion/env/lib/python3.8/site-packages/django/views/debug.py", line 94, in technical_500_response
[Sat Mar 20 19:54:42.696935 2021] [wsgi:error] [pid 212786:tid 140398061483776] [remote 103.119.102.3:36844]     html = reporter.get_traceback_html()
[Sat Mar 20 19:54:42.696976 2021] [wsgi:error] [pid 212786:tid 140398061483776] [remote 103.119.102.3:36844]   File "/home/salesvizion/salesvizion/env/lib/python3.8/site-packages/django/views/debug.py", line 332, in get_traceback_html
[Sat Mar 20 19:54:42.697016 2021] [wsgi:error] [pid 212786:tid 140398061483776] [remote 103.119.102.3:36844]     t = DEBUG_ENGINE.from_string(fh.read())
[Sat Mar 20 19:54:42.697057 2021] [wsgi:error] [pid 212786:tid 140398061483776] [remote 103.119.102.3:36844]   File "/usr/lib/python3.8/encodings/ascii.py", line 26, in decode
[Sat Mar 20 19:54:42.697097 2021] [wsgi:error] [pid 212786:tid 140398061483776] [remote 103.119.102.3:36844]     return codecs.ascii_decode(input, self.errors)[0]
[Sat Mar 20 19:54:42.697151 2021] [wsgi:error] [pid 212786:tid 140398061483776] [remote 103.119.102.3:36844] UnicodeDecodeError: 'ascii' codec can't decode byte 0xe2 in position 9735: ordinal not in range(128)
[Sat Mar 20 19:54:42.697212 2021] [wsgi:error] [pid 212786:tid 140398061483776] [remote 103.119.102.3:36844] 
[Sat Mar 20 19:54:42.697252 2021] [wsgi:error] [pid 212786:tid 140398061483776] [remote 103.119.102.3:36844] During handling of the above exception, another exception occurred:
[Sat Mar 20 19:54:42.697281 2021] [wsgi:error] [pid 212786:tid 140398061483776] [remote 103.119.102.3:36844] 
[Sat Mar 20 19:54:42.697326 2021] [wsgi:error] [pid 212786:tid 140398061483776] [remote 103.119.102.3:36844] Traceback (most recent call last):
[Sat Mar 20 19:54:42.697423 2021] [wsgi:error] [pid 212786:tid 140398061483776] [remote 103.119.102.3:36844]   File "/home/salesvizion/salesvizion/env/lib/python3.8/site-packages/django/core/handlers/exception.py", line 34, in inner
[Sat Mar 20 19:54:42.697469 2021] [wsgi:error] [pid 212786:tid 140398061483776] [remote 103.119.102.3:36844]     response = get_response(request)
[Sat Mar 20 19:54:42.697512 2021] [wsgi:error] [pid 212786:tid 140398061483776] [remote 103.119.102.3:36844]   File "/home/salesvizion/salesvizion/env/lib/python3.8/site-packages/django/utils/deprecation.py", line 94, in __call__
[Sat Mar 20 19:54:42.697570 2021] [wsgi:error] [pid 212786:tid 140398061483776] [remote 103.119.102.3:36844]     response = response or self.get_response(request)
[Sat Mar 20 19:54:42.697674 2021] [wsgi:error] [pid 212786:tid 140398061483776] [remote 103.119.102.3:36844]   File "/home/salesvizion/salesvizion/env/lib/python3.8/site-packages/django/core/handlers/exception.py", line 36, in inner
[Sat Mar 20 19:54:42.697721 2021] [wsgi:error] [pid 212786:tid 140398061483776] [remote 103.119.102.3:36844]     response = response_for_exception(request, exc)
[Sat Mar 20 19:54:42.697764 2021] [wsgi:error] [pid 212786:tid 140398061483776] [remote 103.119.102.3:36844]   File "/home/salesvizion/salesvizion/env/lib/python3.8/site-packages/django/core/handlers/exception.py", line 90, in response_for_exception
[Sat Mar 20 19:54:42.697804 2021] [wsgi:error] [pid 212786:tid 140398061483776] [remote 103.119.102.3:36844]     response = handle_uncaught_exception(request, get_resolver(get_urlconf()), sys.exc_info())
[Sat Mar 20 19:54:42.697846 2021] [wsgi:error] [pid 212786:tid 140398061483776] [remote 103.119.102.3:36844]   File "/home/salesvizion/salesvizion/env/lib/python3.8/site-packages/django/core/handlers/exception.py", line 125, in handle_uncaught_exception
[Sat Mar 20 19:54:42.697887 2021] [wsgi:error] [pid 212786:tid 140398061483776] [remote 103.119.102.3:36844]     return debug.technical_500_response(request, *exc_info)
[Sat Mar 20 19:54:42.697929 2021] [wsgi:error] [pid 212786:tid 140398061483776] [remote 103.119.102.3:36844]   File "/home/salesvizion/salesvizion/env/lib/python3.8/site-packages/django/views/debug.py", line 94, in technical_500_response
[Sat Mar 20 19:54:42.697975 2021] [wsgi:error] [pid 212786:tid 140398061483776] [remote 103.119.102.3:36844]     html = reporter.get_traceback_html()
[Sat Mar 20 19:54:42.698017 2021] [wsgi:error] [pid 212786:tid 140398061483776] [remote 103.119.102.3:36844]   File "/home/salesvizion/salesvizion/env/lib/python3.8/site-packages/django/views/debug.py", line 332, in get_traceback_html
[Sat Mar 20 19:54:42.698057 2021] [wsgi:error] [pid 212786:tid 140398061483776] [remote 103.119.102.3:36844]     t = DEBUG_ENGINE.from_string(fh.read())
[Sat Mar 20 19:54:42.698099 2021] [wsgi:error] [pid 212786:tid 140398061483776] [remote 103.119.102.3:36844]   File "/usr/lib/python3.8/encodings/ascii.py", line 26, in decode
[Sat Mar 20 19:54:42.698139 2021] [wsgi:error] [pid 212786:tid 140398061483776] [remote 103.119.102.3:36844]     return codecs.ascii_decode(input, self.errors)[0]
[Sat Mar 20 19:54:42.698191 2021] [wsgi:error] [pid 212786:tid 140398061483776] [remote 103.119.102.3:36844] UnicodeDecodeError: 'ascii' codec can't decode byte 0xe2 in position 9735: ordinal not in range(128)
[Sat Mar 20 19:54:42.698257 2021] [wsgi:error] [pid 212786:tid 140398061483776] [remote 103.119.102.3:36844] 
[Sat Mar 20 19:54:42.698303 2021] [wsgi:error] [pid 212786:tid 140398061483776] [remote 103.119.102.3:36844] During handling of the above exception, another exception occurred:
[Sat Mar 20 19:54:42.698333 2021] [wsgi:error] [pid 212786:tid 140398061483776] [remote 103.119.102.3:36844] 
[Sat Mar 20 19:54:42.698374 2021] [wsgi:error] [pid 212786:tid 140398061483776] [remote 103.119.102.3:36844] Traceback (most recent call last):
[Sat Mar 20 19:54:42.698471 2021] [wsgi:error] [pid 212786:tid 140398061483776] [remote 103.119.102.3:36844]   File "/home/salesvizion/salesvizion/env/lib/python3.8/site-packages/django/core/handlers/exception.py", line 34, in inner
[Sat Mar 20 19:54:42.698517 2021] [wsgi:error] [pid 212786:tid 140398061483776] [remote 103.119.102.3:36844]     response = get_response(request)
[Sat Mar 20 19:54:42.698560 2021] [wsgi:error] [pid 212786:tid 140398061483776] [remote 103.119.102.3:36844]   File "/home/salesvizion/salesvizion/env/lib/python3.8/site-packages/django/utils/deprecation.py", line 94, in __call__
[Sat Mar 20 19:54:42.698600 2021] [wsgi:error] [pid 212786:tid 140398061483776] [remote 103.119.102.3:36844]     response = response or self.get_response(request)
[Sat Mar 20 19:54:42.698678 2021] [wsgi:error] [pid 212786:tid 140398061483776] [remote 103.119.102.3:36844]   File "/home/salesvizion/salesvizion/env/lib/python3.8/site-packages/django/core/handlers/exception.py", line 36, in inner
[Sat Mar 20 19:54:42.698757 2021] [wsgi:error] [pid 212786:tid 140398061483776] [remote 103.119.102.3:36844]     response = response_for_exception(request, exc)
[Sat Mar 20 19:54:42.698811 2021] [wsgi:error] [pid 212786:tid 140398061483776] [remote 103.119.102.3:36844]   File "/home/salesvizion/salesvizion/env/lib/python3.8/site-packages/django/core/handlers/exception.py", line 90, in response_for_exception
[Sat Mar 20 19:54:42.698859 2021] [wsgi:error] [pid 212786:tid 140398061483776] [remote 103.119.102.3:36844]     response = handle_uncaught_exception(request, get_resolver(get_urlconf()), sys.exc_info())
[Sat Mar 20 19:54:42.698901 2021] [wsgi:error] [pid 212786:tid 140398061483776] [remote 103.119.102.3:36844]   File "/home/salesvizion/salesvizion/env/lib/python3.8/site-packages/django/core/handlers/exception.py", line 125, in handle_uncaught_exception
[Sat Mar 20 19:54:42.698941 2021] [wsgi:error] [pid 212786:tid 140398061483776] [remote 103.119.102.3:36844]     return debug.technical_500_response(request, *exc_info)
[Sat Mar 20 19:54:42.698983 2021] [wsgi:error] [pid 212786:tid 140398061483776] [remote 103.119.102.3:36844]   File "/home/salesvizion/salesvizion/env/lib/python3.8/site-packages/django/views/debug.py", line 94, in technical_500_response
[Sat Mar 20 19:54:42.699022 2021] [wsgi:error] [pid 212786:tid 140398061483776] [remote 103.119.102.3:36844]     html = reporter.get_traceback_html()
[Sat Mar 20 19:54:42.699072 2021] [wsgi:error] [pid 212786:tid 140398061483776] [remote 103.119.102.3:36844]   File "/home/salesvizion/salesvizion/env/lib/python3.8/site-packages/django/views/debug.py", line 332, in get_traceback_html
[Sat Mar 20 19:54:42.699109 2021] [wsgi:error] [pid 212786:tid 140398061483776] [remote 103.119.102.3:36844]     t = DEBUG_ENGINE.from_string(fh.read())
[Sat Mar 20 19:54:42.699149 2021] [wsgi:error] [pid 212786:tid 140398061483776] [remote 103.119.102.3:36844]   File "/usr/lib/python3.8/encodings/ascii.py", line 26, in decode
[Sat Mar 20 19:54:42.699185 2021] [wsgi:error] [pid 212786:tid 140398061483776] [remote 103.119.102.3:36844]     return codecs.ascii_decode(input, self.errors)[0]
[Sat Mar 20 19:54:42.699235 2021] [wsgi:error] [pid 212786:tid 140398061483776] [remote 103.119.102.3:36844] UnicodeDecodeError: 'ascii' codec can't decode byte 0xe2 in position 9735: ordinal not in range(128)
[Sat Mar 20 19:54:42.699293 2021] [wsgi:error] [pid 212786:tid 140398061483776] [remote 103.119.102.3:36844] 
[Sat Mar 20 19:54:42.699331 2021] [wsgi:error] [pid 212786:tid 140398061483776] [remote 103.119.102.3:36844] During handling of the above exception, another exception occurred:
[Sat Mar 20 19:54:42.699358 2021] [wsgi:error] [pid 212786:tid 140398061483776] [remote 103.119.102.3:36844] 
[Sat Mar 20 19:54:42.699397 2021] [wsgi:error] [pid 212786:tid 140398061483776] [remote 103.119.102.3:36844] Traceback (most recent call last):
[Sat Mar 20 19:54:42.699487 2021] [wsgi:error] [pid 212786:tid 140398061483776] [remote 103.119.102.3:36844]   File "/home/salesvizion/salesvizion/env/lib/python3.8/site-packages/django/core/handlers/exception.py", line 34, in inner
[Sat Mar 20 19:54:42.699531 2021] [wsgi:error] [pid 212786:tid 140398061483776] [remote 103.119.102.3:36844]     response = get_response(request)
[Sat Mar 20 19:54:42.699571 2021] [wsgi:error] [pid 212786:tid 140398061483776] [remote 103.119.102.3:36844]   File "/home/salesvizion/salesvizion/env/lib/python3.8/site-packages/django/utils/deprecation.py", line 94, in __call__
[Sat Mar 20 19:54:42.699609 2021] [wsgi:error] [pid 212786:tid 140398061483776] [remote 103.119.102.3:36844]     response = response or self.get_response(request)
[Sat Mar 20 19:54:42.699686 2021] [wsgi:error] [pid 212786:tid 140398061483776] [remote 103.119.102.3:36844]   File "/home/salesvizion/salesvizion/env/lib/python3.8/site-packages/django/core/handlers/exception.py", line 36, in inner
[Sat Mar 20 19:54:42.699730 2021] [wsgi:error] [pid 212786:tid 140398061483776] [remote 103.119.102.3:36844]     response = response_for_exception(request, exc)
[Sat Mar 20 19:54:42.699782 2021] [wsgi:error] [pid 212786:tid 140398061483776] [remote 103.119.102.3:36844]   File "/home/salesvizion/salesvizion/env/lib/python3.8/site-packages/django/core/handlers/exception.py", line 90, in response_for_exception
[Sat Mar 20 19:54:42.699822 2021] [wsgi:error] [pid 212786:tid 140398061483776] [remote 103.119.102.3:36844]     response = handle_uncaught_exception(request, get_resolver(get_urlconf()), sys.exc_info())
[Sat Mar 20 19:54:42.699865 2021] [wsgi:error] [pid 212786:tid 140398061483776] [remote 103.119.102.3:36844]   File "/home/salesvizion/salesvizion/env/lib/python3.8/site-packages/django/core/handlers/exception.py", line 125, in handle_uncaught_exception
[Sat Mar 20 19:54:42.699903 2021] [wsgi:error] [pid 212786:tid 140398061483776] [remote 103.119.102.3:36844]     return debug.technical_500_response(request, *exc_info)
[Sat Mar 20 19:54:42.699942 2021] [wsgi:error] [pid 212786:tid 140398061483776] [remote 103.119.102.3:36844]   File "/home/salesvizion/salesvizion/env/lib/python3.8/site-packages/django/views/debug.py", line 94, in technical_500_response
[Sat Mar 20 19:54:42.699979 2021] [wsgi:error] [pid 212786:tid 140398061483776] [remote 103.119.102.3:36844]     html = reporter.get_traceback_html()
[Sat Mar 20 19:54:42.700017 2021] [wsgi:error] [pid 212786:tid 140398061483776] [remote 103.119.102.3:36844]   File "/home/salesvizion/salesvizion/env/lib/python3.8/site-packages/django/views/debug.py", line 332, in get_traceback_html
[Sat Mar 20 19:54:42.700054 2021] [wsgi:error] [pid 212786:tid 140398061483776] [remote 103.119.102.3:36844]     t = DEBUG_ENGINE.from_string(fh.read())
[Sat Mar 20 19:54:42.700093 2021] [wsgi:error] [pid 212786:tid 140398061483776] [remote 103.119.102.3:36844]   File "/usr/lib/python3.8/encodings/ascii.py", line 26, in decode
[Sat Mar 20 19:54:42.700131 2021] [wsgi:error] [pid 212786:tid 140398061483776] [remote 103.119.102.3:36844]     return codecs.ascii_decode(input, self.errors)[0]
[Sat Mar 20 19:54:42.700180 2021] [wsgi:error] [pid 212786:tid 140398061483776] [remote 103.119.102.3:36844] UnicodeDecodeError: 'ascii' codec can't decode byte 0xe2 in position 9735: ordinal not in range(128)
[Sat Mar 20 19:54:42.700244 2021] [wsgi:error] [pid 212786:tid 140398061483776] [remote 103.119.102.3:36844] 
[Sat Mar 20 19:54:42.700282 2021] [wsgi:error] [pid 212786:tid 140398061483776] [remote 103.119.102.3:36844] During handling of the above exception, another exception occurred:
[Sat Mar 20 19:54:42.700310 2021] [wsgi:error] [pid 212786:tid 140398061483776] [remote 103.119.102.3:36844] 
[Sat Mar 20 19:54:42.700349 2021] [wsgi:error] [pid 212786:tid 140398061483776] [remote 103.119.102.3:36844] Traceback (most recent call last):
[Sat Mar 20 19:54:42.700437 2021] [wsgi:error] [pid 212786:tid 140398061483776] [remote 103.119.102.3:36844]   File "/home/salesvizion/salesvizion/env/lib/python3.8/site-packages/django/core/handlers/exception.py", line 34, in inner
[Sat Mar 20 19:54:42.700481 2021] [wsgi:error] [pid 212786:tid 140398061483776] [remote 103.119.102.3:36844]     response = get_response(request)
[Sat Mar 20 19:54:42.700559 2021] [wsgi:error] [pid 212786:tid 140398061483776] [remote 103.119.102.3:36844]   File "/home/salesvizion/salesvizion/env/lib/python3.8/site-packages/django/utils/deprecation.py", line 94, in __call__
[Sat Mar 20 19:54:42.700616 2021] [wsgi:error] [pid 212786:tid 140398061483776] [remote 103.119.102.3:36844]     response = response or self.get_response(request)
[Sat Mar 20 19:54:42.700691 2021] [wsgi:error] [pid 212786:tid 140398061483776] [remote 103.119.102.3:36844]   File "/home/salesvizion/salesvizion/env/lib/python3.8/site-packages/django/core/handlers/exception.py", line 36, in inner
[Sat Mar 20 19:54:42.700732 2021] [wsgi:error] [pid 212786:tid 140398061483776] [remote 103.119.102.3:36844]     response = response_for_exception(request, exc)
[Sat Mar 20 19:54:42.700772 2021] [wsgi:error] [pid 212786:tid 140398061483776] [remote 103.119.102.3:36844]   File "/home/salesvizion/salesvizion/env/lib/python3.8/site-packages/django/core/handlers/exception.py", line 90, in response_for_exception
[Sat Mar 20 19:54:42.700847 2021] [wsgi:error] [pid 212786:tid 140398061483776] [remote 103.119.102.3:36844]     response = handle_uncaught_exception(request, get_resolver(get_urlconf()), sys.exc_info())
[Sat Mar 20 19:54:42.700898 2021] [wsgi:error] [pid 212786:tid 140398061483776] [remote 103.119.102.3:36844]   File "/home/salesvizion/salesvizion/env/lib/python3.8/site-packages/django/core/handlers/exception.py", line 125, in handle_uncaught_exception
[Sat Mar 20 19:54:42.700938 2021] [wsgi:error] [pid 212786:tid 140398061483776] [remote 103.119.102.3:36844]     return debug.technical_500_response(request, *exc_info)
[Sat Mar 20 19:54:42.700978 2021] [wsgi:error] [pid 212786:tid 140398061483776] [remote 103.119.102.3:36844]   File "/home/salesvizion/salesvizion/env/lib/python3.8/site-packages/django/views/debug.py", line 94, in technical_500_response
[Sat Mar 20 19:54:42.701016 2021] [wsgi:error] [pid 212786:tid 140398061483776] [remote 103.119.102.3:36844]     html = reporter.get_traceback_html()
[Sat Mar 20 19:54:42.701055 2021] [wsgi:error] [pid 212786:tid 140398061483776] [remote 103.119.102.3:36844]   File "/home/salesvizion/salesvizion/env/lib/python3.8/site-packages/django/views/debug.py", line 332, in get_traceback_html
[Sat Mar 20 19:54:42.701092 2021] [wsgi:error] [pid 212786:tid 140398061483776] [remote 103.119.102.3:36844]     t = DEBUG_ENGINE.from_string(fh.read())
[Sat Mar 20 19:54:42.701131 2021] [wsgi:error] [pid 212786:tid 140398061483776] [remote 103.119.102.3:36844]   File "/usr/lib/python3.8/encodings/ascii.py", line 26, in decode
[Sat Mar 20 19:54:42.701168 2021] [wsgi:error] [pid 212786:tid 140398061483776] [remote 103.119.102.3:36844]     return codecs.ascii_decode(input, self.errors)[0]
[Sat Mar 20 19:54:42.701218 2021] [wsgi:error] [pid 212786:tid 140398061483776] [remote 103.119.102.3:36844] UnicodeDecodeError: 'ascii' codec can't decode byte 0xe2 in position 9735: ordinal not in range(128)
[Sat Mar 20 19:54:42.701283 2021] [wsgi:error] [pid 212786:tid 140398061483776] [remote 103.119.102.3:36844] 
[Sat Mar 20 19:54:42.701322 2021] [wsgi:error] [pid 212786:tid 140398061483776] [remote 103.119.102.3:36844] During handling of the above exception, another exception occurred:
[Sat Mar 20 19:54:42.701350 2021] [wsgi:error] [pid 212786:tid 140398061483776] [remote 103.119.102.3:36844] 
[Sat Mar 20 19:54:42.701389 2021] [wsgi:error] [pid 212786:tid 140398061483776] [remote 103.119.102.3:36844] Traceback (most recent call last):
[Sat Mar 20 19:54:42.701478 2021] [wsgi:error] [pid 212786:tid 140398061483776] [remote 103.119.102.3:36844]   File "/home/salesvizion/salesvizion/env/lib/python3.8/site-packages/django/core/handlers/wsgi.py", line 141, in __call__
[Sat Mar 20 19:54:42.701522 2021] [wsgi:error] [pid 212786:tid 140398061483776] [remote 103.119.102.3:36844]     response = self.get_response(request)
[Sat Mar 20 19:54:42.701564 2021] [wsgi:error] [pid 212786:tid 140398061483776] [remote 103.119.102.3:36844]   File "/home/salesvizion/salesvizion/env/lib/python3.8/site-packages/django/core/handlers/base.py", line 75, in get_response
[Sat Mar 20 19:54:42.701607 2021] [wsgi:error] [pid 212786:tid 140398061483776] [remote 103.119.102.3:36844]     response = self._middleware_chain(request)
[Sat Mar 20 19:54:42.701672 2021] [wsgi:error] [pid 212786:tid 140398061483776] [remote 103.119.102.3:36844]   File "/home/salesvizion/salesvizion/env/lib/python3.8/site-packages/django/core/handlers/exception.py", line 36, in inner
[Sat Mar 20 19:54:42.701728 2021] [wsgi:error] [pid 212786:tid 140398061483776] [remote 103.119.102.3:36844]     response = response_for_exception(request, exc)
[Sat Mar 20 19:54:42.701778 2021] [wsgi:error] [pid 212786:tid 140398061483776] [remote 103.119.102.3:36844]   File "/home/salesvizion/salesvizion/env/lib/python3.8/site-packages/django/core/handlers/exception.py", line 90, in response_for_exception
[Sat Mar 20 19:54:42.701822 2021] [wsgi:error] [pid 212786:tid 140398061483776] [remote 103.119.102.3:36844]     response = handle_uncaught_exception(request, get_resolver(get_urlconf()), sys.exc_info())
[Sat Mar 20 19:54:42.701906 2021] [wsgi:error] [pid 212786:tid 140398061483776] [remote 103.119.102.3:36844]   File "/home/salesvizion/salesvizion/env/lib/python3.8/site-packages/django/core/handlers/exception.py", line 125, in handle_uncaught_exception
[Sat Mar 20 19:54:42.701948 2021] [wsgi:error] [pid 212786:tid 140398061483776] [remote 103.119.102.3:36844]     return debug.technical_500_response(request, *exc_info)
[Sat Mar 20 19:54:42.701988 2021] [wsgi:error] [pid 212786:tid 140398061483776] [remote 103.119.102.3:36844]   File "/home/salesvizion/salesvizion/env/lib/python3.8/site-packages/django/views/debug.py", line 94, in technical_500_response
[Sat Mar 20 19:54:42.702025 2021] [wsgi:error] [pid 212786:tid 140398061483776] [remote 103.119.102.3:36844]     html = reporter.get_traceback_html()
[Sat Mar 20 19:54:42.702070 2021] [wsgi:error] [pid 212786:tid 140398061483776] [remote 103.119.102.3:36844]   File "/home/salesvizion/salesvizion/env/lib/python3.8/site-packages/django/views/debug.py", line 332, in get_traceback_html
[Sat Mar 20 19:54:42.702108 2021] [wsgi:error] [pid 212786:tid 140398061483776] [remote 103.119.102.3:36844]     t = DEBUG_ENGINE.from_string(fh.read())
[Sat Mar 20 19:54:42.702146 2021] [wsgi:error] [pid 212786:tid 140398061483776] [remote 103.119.102.3:36844]   File "/usr/lib/python3.8/encodings/ascii.py", line 26, in decode
[Sat Mar 20 19:54:42.702183 2021] [wsgi:error] [pid 212786:tid 140398061483776] [remote 103.119.102.3:36844]     return codecs.ascii_decode(input, self.errors)[0]
[Sat Mar 20 19:54:42.702233 2021] [wsgi:error] [pid 212786:tid 140398061483776] [remote 103.119.102.3:36844] UnicodeDecodeError: 'ascii' codec can't decode byte 0xe2 in position 9735: ordinal not in range(128)
